<?xml version="1.0" ?>
<robot name="arm_5dof" xmlns:xacro="http://www.ros.org/wiki/xacro">

<xacro:include filename="$(find arm_5dof_description)/urdf/materials.xacro" />
<xacro:include filename="$(find arm_5dof_description)/urdf/arm_5dof.trans" />
<xacro:include filename="$(find arm_5dof_description)/urdf/arm_5dof.gazebo" />
<link name="base_link">
  <inertial>
    <origin xyz="0.003838009810151215 0.0004461779457259607 0.02286877876994561" rpy="0 0 0"/>
    <mass value="0.7522188043041829"/>
    <inertia ixx="0.001001" iyy="0.00108" izz="0.001629" ixy="0.0" iyz="-1e-06" ixz="3.1e-05"/>
  </inertial>
  <visual>
    <origin xyz="0 0 0" rpy="0 0 0"/>
    <geometry>
      <mesh filename="package://arm_5dof_description/meshes/base_link.stl" scale="0.001 0.001 0.001"/>
    </geometry>
    <material name="silver"/>
  </visual>
  <collision>
    <origin xyz="0 0 0" rpy="0 0 0"/>
    <geometry>
      <mesh filename="package://arm_5dof_description/meshes/base_link.stl" scale="0.001 0.001 0.001"/>
    </geometry>
  </collision>
</link>

<link name="waist_1">
  <inertial>
    <origin xyz="-0.006392051753752244 0.001401748909597569 0.01727759625271507" rpy="0 0 0"/>
    <mass value="0.5354437528567239"/>
    <inertia ixx="0.000458" iyy="0.000356" izz="0.000432" ixy="5e-06" iyz="-4.9e-05" ixz="4.1e-05"/>
  </inertial>
  <visual>
    <origin xyz="-0.003713 -0.000323 -0.056611" rpy="0 0 0"/>
    <geometry>
      <mesh filename="package://arm_5dof_description/meshes/waist_1.stl" scale="0.001 0.001 0.001"/>
    </geometry>
    <material name="silver"/>
  </visual>
  <collision>
    <origin xyz="-0.003713 -0.000323 -0.056611" rpy="0 0 0"/>
    <geometry>
      <mesh filename="package://arm_5dof_description/meshes/waist_1.stl" scale="0.001 0.001 0.001"/>
    </geometry>
  </collision>
</link>

<link name="arm1_1">
  <inertial>
    <origin xyz="0.007777186996678871 7.774960774779502e-06 0.06126573841870464" rpy="0 0 0"/>
    <mass value="0.5212036434465369"/>
    <inertia ixx="0.000993" iyy="0.000951" izz="7.6e-05" ixy="0.0" iyz="-0.0" ixz="-2e-06"/>
  </inertial>
  <visual>
    <origin xyz="0.000287 -0.014242 -0.096887" rpy="0 0 0"/>
    <geometry>
      <mesh filename="package://arm_5dof_description/meshes/arm1_1.stl" scale="0.001 0.001 0.001"/>
    </geometry>
    <material name="silver"/>
  </visual>
  <collision>
    <origin xyz="0.000287 -0.014242 -0.096887" rpy="0 0 0"/>
    <geometry>
      <mesh filename="package://arm_5dof_description/meshes/arm1_1.stl" scale="0.001 0.001 0.001"/>
    </geometry>
  </collision>
</link>

<link name="arm2_1">
  <inertial>
    <origin xyz="-0.0074056876684373924 -2.2168026232168708e-05 0.03928210706367469" rpy="0 0 0"/>
    <mass value="0.3945467908121779"/>
    <inertia ixx="0.000457" iyy="0.000429" izz="7.3e-05" ixy="-0.0" iyz="1e-06" ixz="2e-06"/>
  </inertial>
  <visual>
    <origin xyz="0.000287 -0.014242 -0.216887" rpy="0 0 0"/>
    <geometry>
      <mesh filename="package://arm_5dof_description/meshes/arm2_1.stl" scale="0.001 0.001 0.001"/>
    </geometry>
    <material name="silver"/>
  </visual>
  <collision>
    <origin xyz="0.000287 -0.014242 -0.216887" rpy="0 0 0"/>
    <geometry>
      <mesh filename="package://arm_5dof_description/meshes/arm2_1.stl" scale="0.001 0.001 0.001"/>
    </geometry>
  </collision>
</link>

<link name="arm3_1">
  <inertial>
    <origin xyz="0.005266858431944335 -0.005042877072588029 0.01784090117232645" rpy="0 0 0"/>
    <mass value="0.12951657013229365"/>
    <inertia ixx="3.9e-05" iyy="3.1e-05" izz="2.1e-05" ixy="-0.0" iyz="-0.0" ixz="-5e-06"/>
  </inertial>
  <visual>
    <origin xyz="0.007787 -0.019542 -0.306637" rpy="0 0 0"/>
    <geometry>
      <mesh filename="package://arm_5dof_description/meshes/arm3_1.stl" scale="0.001 0.001 0.001"/>
    </geometry>
    <material name="silver"/>
  </visual>
  <collision>
    <origin xyz="0.007787 -0.019542 -0.306637" rpy="0 0 0"/>
    <geometry>
      <mesh filename="package://arm_5dof_description/meshes/arm3_1.stl" scale="0.001 0.001 0.001"/>
    </geometry>
  </collision>
</link>

<link name="gripper1_1">
  <inertial>
    <origin xyz="0.004578043352201293 0.003949278321660978 0.026923966453247516" rpy="0 0 0"/>
    <mass value="0.04237033350998682"/>
    <inertia ixx="1.3e-05" iyy="1.3e-05" izz="1e-06" ixy="0.0" iyz="0.0" ixz="-1e-06"/>
  </inertial>
  <visual>
    <origin xyz="0.042429 -0.000102 -0.372478" rpy="0 0 0"/>
    <geometry>
      <mesh filename="package://arm_5dof_description/meshes/gripper1_1.stl" scale="0.001 0.001 0.001"/>
    </geometry>
    <material name="silver"/>
  </visual>
  <collision>
    <origin xyz="0.042429 -0.000102 -0.372478" rpy="0 0 0"/>
    <geometry>
      <mesh filename="package://arm_5dof_description/meshes/gripper1_1.stl" scale="0.001 0.001 0.001"/>
    </geometry>
  </collision>
</link>

<link name="gripper2_1">
  <inertial>
    <origin xyz="-0.004117256812935996 0.003945625879510171 0.026999145762990784" rpy="0 0 0"/>
    <mass value="0.042370329631280915"/>
    <inertia ixx="1.3e-05" iyy="1.3e-05" izz="1e-06" ixy="-0.0" iyz="0.0" ixz="1e-06"/>
  </inertial>
  <visual>
    <origin xyz="-0.045971 -0.000138 -0.372478" rpy="0 0 0"/>
    <geometry>
      <mesh filename="package://arm_5dof_description/meshes/gripper2_1.stl" scale="0.001 0.001 0.001"/>
    </geometry>
    <material name="silver"/>
  </visual>
  <collision>
    <origin xyz="-0.045971 -0.000138 -0.372478" rpy="0 0 0"/>
    <geometry>
      <mesh filename="package://arm_5dof_description/meshes/gripper2_1.stl" scale="0.001 0.001 0.001"/>
    </geometry>
  </collision>
</link>

<link name="gripper_base_1">
  <inertial>
    <origin xyz="-0.0019741960439591272 -0.006082068799121706 0.023484597423749975" rpy="0 0 0"/>
    <mass value="0.12341306540761511"/>
    <inertia ixx="5.7e-05" iyy="6.3e-05" izz="2e-05" ixy="-3e-06" iyz="1.1e-05" ixz="1.1e-05"/>
  </inertial>
  <visual>
    <origin xyz="-0.006215 -0.014548 -0.334637" rpy="0 0 0"/>
    <geometry>
      <mesh filename="package://arm_5dof_description/meshes/gripper_base_1.stl" scale="0.001 0.001 0.001"/>
    </geometry>
    <material name="silver"/>
  </visual>
  <collision>
    <origin xyz="-0.006215 -0.014548 -0.334637" rpy="0 0 0"/>
    <geometry>
      <mesh filename="package://arm_5dof_description/meshes/gripper_base_1.stl" scale="0.001 0.001 0.001"/>
    </geometry>
  </collision>
</link>

<link name="gear1_1">
  <inertial>
    <origin xyz="-0.00557822139075125 -0.0020086168818973663 0.0005788433778717295" rpy="0 0 0"/>
    <mass value="0.020736163200801024"/>
    <inertia ixx="1e-06" iyy="4e-06" izz="3e-06" ixy="-0.0" iyz="0.0" ixz="-0.0"/>
  </inertial>
  <visual>
    <origin xyz="0.011679 -0.000114 -0.372478" rpy="0 0 0"/>
    <geometry>
      <mesh filename="package://arm_5dof_description/meshes/gear1_1.stl" scale="0.001 0.001 0.001"/>
    </geometry>
    <material name="silver"/>
  </visual>
  <collision>
    <origin xyz="0.011679 -0.000114 -0.372478" rpy="0 0 0"/>
    <geometry>
      <mesh filename="package://arm_5dof_description/meshes/gear1_1.stl" scale="0.001 0.001 0.001"/>
    </geometry>
  </collision>
</link>

<link name="gear2_1">
  <inertial>
    <origin xyz="0.005666401849291939 -0.0020039311247486507 0.0005815410560265355" rpy="0 0 0"/>
    <mass value="0.020141547493382938"/>
    <inertia ixx="1e-06" iyy="4e-06" izz="3e-06" ixy="-0.0" iyz="0.0" ixz="0.0"/>
  </inertial>
  <visual>
    <origin xyz="-0.015221 -0.000125 -0.372478" rpy="0 0 0"/>
    <geometry>
      <mesh filename="package://arm_5dof_description/meshes/gear2_1.stl" scale="0.001 0.001 0.001"/>
    </geometry>
    <material name="silver"/>
  </visual>
  <collision>
    <origin xyz="-0.015221 -0.000125 -0.372478" rpy="0 0 0"/>
    <geometry>
      <mesh filename="package://arm_5dof_description/meshes/gear2_1.stl" scale="0.001 0.001 0.001"/>
    </geometry>
  </collision>
</link>

<link name="sg90_1_1">
  <inertial>
    <origin xyz="-1.350399744179387e-07 0.013371543082314133 -0.005539058375771733" rpy="0 0 0"/>
    <mass value="0.1678780953403671"/>
    <inertia ixx="1.7e-05" iyy="1.1e-05" izz="1e-05" ixy="-0.0" iyz="1e-06" ixz="0.0"/>
  </inertial>
  <visual>
    <origin xyz="0.007787 -0.000442 -0.296637" rpy="0 0 0"/>
    <geometry>
      <mesh filename="package://arm_5dof_description/meshes/sg90_1_1.stl" scale="0.001 0.001 0.001"/>
    </geometry>
    <material name="silver"/>
  </visual>
  <collision>
    <origin xyz="0.007787 -0.000442 -0.296637" rpy="0 0 0"/>
    <geometry>
      <mesh filename="package://arm_5dof_description/meshes/sg90_1_1.stl" scale="0.001 0.001 0.001"/>
    </geometry>
  </collision>
</link>

<link name="sg90_1_2">
  <inertial>
    <origin xyz="-0.0055394403309275515 -1.861104244056666e-06 0.014228730965407776" rpy="0 0 0"/>
    <mass value="0.1678780953403671"/>
    <inertia ixx="1e-05" iyy="1.7e-05" izz="1.1e-05" ixy="-0.0" iyz="-0.0" ixz="-1e-06"/>
  </inertial>
  <visual>
    <origin xyz="0.004285 -0.014543 -0.315837" rpy="0 0 0"/>
    <geometry>
      <mesh filename="package://arm_5dof_description/meshes/sg90_1_2.stl" scale="0.001 0.001 0.001"/>
    </geometry>
    <material name="silver"/>
  </visual>
  <collision>
    <origin xyz="0.004285 -0.014543 -0.315837" rpy="0 0 0"/>
    <geometry>
      <mesh filename="package://arm_5dof_description/meshes/sg90_1_2.stl" scale="0.001 0.001 0.001"/>
    </geometry>
  </collision>
</link>

<link name="sg90_1_3">
  <inertial>
    <origin xyz="0.013368816698144156 0.005544542448326065 6.180991207238584e-05" rpy="0 0 0"/>
    <mass value="0.1678780953403671"/>
    <inertia ixx="1.1e-05" iyy="1e-05" izz="1.7e-05" ixy="-1e-06" iyz="-0.0" ixz="-0.0"/>
  </inertial>
  <visual>
    <origin xyz="0.020483 -0.01061 -0.372596" rpy="0 0 0"/>
    <geometry>
      <mesh filename="package://arm_5dof_description/meshes/sg90_1_3.stl" scale="0.001 0.001 0.001"/>
    </geometry>
    <material name="silver"/>
  </visual>
  <collision>
    <origin xyz="0.020483 -0.01061 -0.372596" rpy="0 0 0"/>
    <geometry>
      <mesh filename="package://arm_5dof_description/meshes/sg90_1_3.stl" scale="0.001 0.001 0.001"/>
    </geometry>
  </collision>
</link>

<link name="mg996r_1_1">
  <inertial>
    <origin xyz="-0.023509816880881013 0.005000482971852852 -0.010842185562066939" rpy="0 0 0"/>
    <mass value="0.7977944565420556"/>
    <inertia ixx="0.000138" iyy="0.000226" izz="0.000142" ixy="-0.0" iyz="-0.0" ixz="-6e-06"/>
  </inertial>
  <visual>
    <origin xyz="-0.017463 0.004677 -0.038611" rpy="0 0 0"/>
    <geometry>
      <mesh filename="package://arm_5dof_description/meshes/mg996r_1_1.stl" scale="0.001 0.001 0.001"/>
    </geometry>
    <material name="silver"/>
  </visual>
  <collision>
    <origin xyz="-0.017463 0.004677 -0.038611" rpy="0 0 0"/>
    <geometry>
      <mesh filename="package://arm_5dof_description/meshes/mg996r_1_1.stl" scale="0.001 0.001 0.001"/>
    </geometry>
  </collision>
</link>

<link name="mg996r_1_2">
  <inertial>
    <origin xyz="-0.010842080696952678 0.013781838936363068 0.02085308595696858" rpy="0 0 0"/>
    <mass value="0.7977944565420556"/>
    <inertia ixx="0.000142" iyy="0.000182" izz="0.000182" ixy="-5e-06" iyz="-4.4e-05" ixz="-5e-06"/>
  </inertial>
  <visual>
    <origin xyz="0.014287 0.006441 -0.069133" rpy="0 0 0"/>
    <geometry>
      <mesh filename="package://arm_5dof_description/meshes/mg996r_1_2.stl" scale="0.001 0.001 0.001"/>
    </geometry>
    <material name="silver"/>
  </visual>
  <collision>
    <origin xyz="0.014287 0.006441 -0.069133" rpy="0 0 0"/>
    <geometry>
      <mesh filename="package://arm_5dof_description/meshes/mg996r_1_2.stl" scale="0.001 0.001 0.001"/>
    </geometry>
  </collision>
</link>

<link name="mg996r_1_3">
  <inertial>
    <origin xyz="-0.010842088207209402 0.004999978626369209 0.023509974899488584" rpy="0 0 0"/>
    <mass value="0.7977944565420556"/>
    <inertia ixx="0.000142" iyy="0.000226" izz="0.000138" ixy="-0.0" iyz="0.0" ixz="6e-06"/>
  </inertial>
  <visual>
    <origin xyz="0.013287 -0.009242 -0.203137" rpy="0 0 0"/>
    <geometry>
      <mesh filename="package://arm_5dof_description/meshes/mg996r_1_3.stl" scale="0.001 0.001 0.001"/>
    </geometry>
    <material name="silver"/>
  </visual>
  <collision>
    <origin xyz="0.013287 -0.009242 -0.203137" rpy="0 0 0"/>
    <geometry>
      <mesh filename="package://arm_5dof_description/meshes/mg996r_1_3.stl" scale="0.001 0.001 0.001"/>
    </geometry>
  </collision>
</link>

<joint name="joint1" type="revolute">
  <origin xyz="0.003713 0.000323 0.056611" rpy="0 0 0"/>
  <parent link="base_link"/>
  <child link="waist_1"/>
  <axis xyz="0.0 -0.0 1.0"/>
  <limit upper="1.570796" lower="-1.570796" effort="100" velocity="100"/>
</joint>

<joint name="joint2" type="revolute">
  <origin xyz="-0.004 0.013919 0.040276" rpy="0 0 0"/>
  <parent link="waist_1"/>
  <child link="arm1_1"/>
  <axis xyz="1.0 0.0 0.0"/>
  <limit upper="1.570796" lower="-1.570796" effort="100" velocity="100"/>
</joint>

<joint name="joint3" type="revolute">
  <origin xyz="0.0 0.0 0.12" rpy="0 0 0"/>
  <parent link="arm1_1"/>
  <child link="arm2_1"/>
  <axis xyz="-1.0 -0.0 -0.0"/>
  <limit upper="1.570796" lower="-1.570796" effort="100" velocity="100"/>
</joint>

<joint name="joint4" type="revolute">
  <origin xyz="-0.0075 0.0053 0.08975" rpy="0 0 0"/>
  <parent link="arm2_1"/>
  <child link="arm3_1"/>
  <axis xyz="-0.0 0.0 1.0"/>
  <limit upper="1.570796" lower="-1.570796" effort="100" velocity="100"/>
</joint>

<joint name="joint5" type="revolute">
  <origin xyz="0.014002 -0.004994 0.028" rpy="0 0 0"/>
  <parent link="arm3_1"/>
  <child link="gripper_base_1"/>
  <axis xyz="1.0 0.000412 0.0"/>
  <limit upper="1.570796" lower="-1.570796" effort="100" velocity="100"/>
</joint>





<joint name="joint6" type="revolute">
  <origin xyz="-0.017894 -0.014434 0.037841" rpy="0 0 0"/>
  <parent link="gripper_base_1"/>
  <child link="gear1_1"/>
  <axis xyz="0.000412 -0.999937 -0.011235"/>
  <limit upper="0.0" lower="-1.570796" effort="100" velocity="100"/>
</joint>

<joint name="joint7" type="continuous">
  <origin xyz="0.009006 -0.014423 0.037841" rpy="0 0 0"/>
  <parent link="gripper_base_1"/>
  <child link="gear2_1"/>
  <axis xyz="-0.000412 0.999937 0.011235"/>
        <mimic joint="joint6" multiplier="1" offset="0" />
</joint>
<joint name="keep1" type="continuous">
  <origin xyz="-0.03075 -1.2e-05 0.0" rpy="0 0 0"/>
  <parent link="gear1_1"/>
  <child link="gripper1_1"/>
  <axis xyz="0.000412 -0.999937 -0.011235"/>
  <mimic joint="joint6" multiplier="-1" offset="0" />
</joint>

<joint name="keep2" type="continuous">
  <origin xyz="0.03075 1.3e-05 0.0" rpy="0 0 0"/>
  <parent link="gear2_1"/>
  <child link="gripper2_1"/>
  <axis xyz="0.000412 -0.999937 -0.011235"/>
        <mimic joint="joint6" multiplier="1" offset="0" />
</joint>
<joint name="Rigid 30" type="fixed">
  <origin xyz="-0.0075 -0.0138 0.07975" rpy="0 0 0"/>
  <parent link="arm2_1"/>
  <child link="sg90_1_1"/>
</joint>

<joint name="Rigid 31" type="fixed">
  <origin xyz="0.003502 -0.004999 0.0092" rpy="0 0 0"/>
  <parent link="arm3_1"/>
  <child link="sg90_1_2"/>
</joint>

<joint name="Rigid 32" type="fixed">
  <origin xyz="-0.026698 -0.003938 0.037959" rpy="0 0 0"/>
  <parent link="gripper_base_1"/>
  <child link="sg90_1_3"/>
</joint>

<joint name="Rigid 33" type="fixed">
  <origin xyz="0.017463 -0.004677 0.038611" rpy="0 0 0"/>
  <parent link="base_link"/>
  <child link="mg996r_1_1"/>
</joint>

<joint name="Rigid 34" type="fixed">
  <origin xyz="-0.018 -0.006764 0.012522" rpy="0 0 0"/>
  <parent link="waist_1"/>
  <child link="mg996r_1_2"/>
</joint>

<joint name="Rigid 35" type="fixed">
  <origin xyz="-0.013 -0.005 -0.01375" rpy="0 0 0"/>
  <parent link="arm2_1"/>
  <child link="mg996r_1_3"/>
</joint>

</robot>
